Workbook

Sheet Product Breakdown
A1: OCI and AWS Price Compare
B5: Amazon Web Services | E5: Oracle Cloud Infrastructure
B6: AWS Service | E6: OCI Service
B7: Amazon Elastic Compute Cloud | C7: =SUM('AWS Estimate'!F9:F18) -> 8763.5992 | E7: OCI Compute** | F7: =SUM('OCI Estimate'!G15:G86) -> 5607.4804
B8: Amazon WorkSpaces | C8: =('AWS Estimate'!F23) -> 1470 | E8: Secure Desktop | F8: =SUM('OCI Estimate'!G8:G13) -> 1628.2
B9: Amazon DynamoDB | C9: =('AWS Estimate'!F22) -> 62.5 | E9: OCI Compute w/ NoSQL | F9: =SUM('OCI Estimate'!G92:G96) -> 55.685067
B10: Elastic Load Balancing | C10: =('AWS Estimate'!F24) -> 33.32 | E10: Flexible Load Balancer | F10: =SUM('OCI Estimate'!G88:G90) -> 8.0908
B11: Amazon Simple Storage Service | C11: =('AWS Estimate'!F19) -> 23.05 | E11: Object Storage | F11: =SUM('OCI Estimate'!G98:G101) -> 59.228
B12: Amazon File Storage | C12: ='AWS Estimate'!F21 -> 30 | E12: File Storage | F12: =SUM('OCI Estimate'!G103) -> 30
B13: AWS Data Transfer | C13: 0 | E13: OCI Data Transfer** | F13: 0
B14: Amazon Virtual Private Cloud | C14: 0 | E14: Virtual Cloud Network | F14: 0
E15: FastConnect 1Gbps Port | F15: 158.1
B16: AmazonCloudWatch | C16: 0 | E16: OCI Logging | F16: 0
B17: AWS Security Hub | C17: 0 | E17: Cloud Guard | F17: 0
B18: Direct Connect 1Gbps Port | C18: ='AWS Estimate'!F26 -> 478.96 | E18: FastConnect 1Gbps Port | F18: ='OCI Estimate'!G105 -> 310.25
B19: AWS Secrets Manager | C19: 0 | E19: Secrets Management with OCI Vault | F19: 0
B20: Tax | C20: TBD | E20: VPN | F20: 0
B21: Total AWS - Monthly | C21: =SUM(C7:C13,C18) -> 10861.429 | E21: Enterprise Support7x24 365 | F21: 0
B22: Total AWS - Yearly | C22: =PRODUCT(C21*12) -> 130337.15 | E22: Tax | F22: TBD
B23: Total AWS - 3yrs | C23: =PRODUCT(C22*3) -> 391011.45 | E23: Total OCI - Monthly | F23: =SUM(F7:F12,F18) -> 7698.9342 | G23: Monthly Cost Savings on OCI | H23: =C21-F23 -> 3162.495
B24: Total AWS - 5yrs | C24: =PRODUCT(C22*5) -> 651685.75 | E24: Total OCI - Yearly | F24: =PRODUCT(F23*12) -> 92387.211 | G24: Annual Cost Savings on OCI | H24: =C22-F24 -> 37949.939
E25: Total OCI - 3yrs | F25: =PRODUCT(F24*3) -> 277161.63 | G25: 3yr Cost Savings on OCI | H25: =C23-F25 -> 113849.82
E26: Total OCI - 5yrs | F26: =PRODUCT(F24*5) -> 461936.05 | G26: 5yr Cost Savings on OCI | H26: =C24-F26 -> 189749.7
A34: **All priced on Windows Server (LI)
A35: **Data Transfer based on 2TB with FastConnect and DirectConnect of outbound transfer

Sheet Product Breakdown + DR
A1: OCI and AWS Price Compare
A2: DIASTER RECOVERY (Warm DR)
B5: Amazon Web Services | E5: Oracle Cloud Infrastructure
B6: AWS Service | E6: OCI Service
B7: Amazon Elastic Compute Cloud | C7: =SUM(C35,'Product Breakdown'!C7) -> 13145.399 | E7: OCI Compute | F7: =SUM(F35,'Product Breakdown'!F7) -> 8411.2206
B8: Amazon WorkSpaces | C8: =SUM(C36,'Product Breakdown'!C8) -> 2205 | E8: Secure Desktop | F8: =SUM(F36,'Product Breakdown'!F8) -> 2442.3
B9: Amazon DynamoDB | C9: =SUM(C37,'Product Breakdown'!C9) -> 93.75 | E9: OCI Compute w/ NoSQL | F9: =SUM(F37,'Product Breakdown'!F9) -> 83.527601
B10: Elastic Load Balancing | C10: =SUM(C38,'Product Breakdown'!C10) -> 49.98 | E10: Flexible Load Balancer | F10: =SUM(F38,'Product Breakdown'!F10) -> 12.1362
B11: Amazon Simple Storage Service | C11: =SUM(C39,'Product Breakdown'!C11) -> 34.575 | E11: Object Storage | F11: =SUM(F39,'Product Breakdown'!F11) -> 88.842
B12: Amazon File Storage | C12: =SUM(C40,'Product Breakdown'!C12) -> 45 | E12: File Storage | F12: =SUM(F40,'Product Breakdown'!F12) -> 45
B13: AWS Data Transfer | C13: =SUM(C41,'Product Breakdown'!C13) -> 0 | E13: OCI Data Transfer | F13: 0
B14: Amazon Virtual Private Cloud | C14: 0 | E14: Virtual Cloud Network | F14: 0
B15: AmazonCloudWatch | C15: 0 | E15: OCI Logging | F15: 0
B16: AWS Security Hub | C16: 0 | E16: Cloud Guard | F16: 0
B17: Direct Connect 1Gbps Port | C17: =SUM(C45,'Product Breakdown'!C18) -> 718.44 | E17: FastConnect 1Gbps Port | F17: =SUM(F45,'Product Breakdown'!F18) -> 465.375
B18: AWS Secrets Manager | C18: 0 | E18: Secrets Management with OCI Vault | F18: 0
B19: Tax | C19: TBD | E19: VPN
B20: Total AWS - Monthly | C20: =SUM(C7:C13,C17) -> 16292.144 | E20: Enterprise Support7x24 365 | F20: 0
B21: Total AWS - Yearly | C21: =PRODUCT(C20*12) -> 195505.73 | E21: Tax | F21: TBD
B22: Total AWS - 3yrs | C22: =PRODUCT(C21*3) -> 586517.18 | E22: Total OCI - Monthly | F22: =SUM(F7:F12,F17) -> 11548.401
B23: Total AWS - 5yrs | C23: =PRODUCT(C21*5) -> 977528.63 | E23: Total OCI - Yearly | F23: =PRODUCT(F22*12) -> 138580.82
E24: Total OCI - 3yrs | F24: =PRODUCT(F23*3) -> 415742.45
E25: Total OCI - 5yrs | F25: =PRODUCT(F23*5) -> 692904.08
E26: Monthly Cost Savings on OCI | F26: =C20-F22 -> 4743.7424
E27: Annual Cost Savings on OCI | F27: =C21-F23 -> 56924.909
E28: 3yr Cost Savings on OCI | F28: =C22-F24 -> 170774.73
E29: 5yr Cost Savings on OCI | F29: =C23-F25 -> 284624.55
A31: Warm DR at 50% Utilization Price
B33: Amazon Web Services | E33: Oracle Cloud Infrastructure
B34: AWS Service | E34: OCI Service
B35: Amazon Elastic Compute Cloud | C35: ='Product Breakdown'!C7/2 -> 4381.7996 | E35: OCI Compute | F35: =('Product Breakdown'!F7/2) -> 2803.7402
B36: Amazon WorkSpaces | C36: ='Product Breakdown'!C8/2 -> 735 | E36: Secure Desktop | F36: ='Product Breakdown'!F8/2 -> 814.1
B37: Amazon DynamoDB | C37: ='Product Breakdown'!C9/2 -> 31.25 | E37: OCI Compute w/ NoSQL | F37: ='Product Breakdown'!F9/2 -> 27.842534
B38: Elastic Load Balancing | C38: ='Product Breakdown'!C10/2 -> 16.66 | E38: Flexible Load Balancer | F38: ='Product Breakdown'!F10/2 -> 4.0454
B39: Amazon Simple Storage Service | C39: =('Product Breakdown'!C11/2) -> 11.525 | E39: Object Storage | F39: ='Product Breakdown'!F11/2 -> 29.614
B40: Amazon File Storage | C40: ='Product Breakdown'!C12/2 -> 15 | E40: File Storage | F40: ='Product Breakdown'!F12/2 -> 15
B41: AWS Data Transfer | C41: ='Product Breakdown'!C13/2 -> 0 | E41: OCI Data Transfer | F41: 0
B42: Amazon Virtual Private Cloud | C42: 0 | E42: Virtual Cloud Network | F42: 0
B43: AmazonCloudWatch | C43: 0 | E43: OCI Logging | F43: 0
B44: AWS Security Hub | C44: 0 | E44: Cloud Guard | F44: 0
...

Sheet OCI Estimate
A1: Oracle Investment Proposal (as of 06/20/2025)
A2: Reference label: CUSTOMER BOM Estimate
A3: Currency: USD
A4: Realm: PUBLIC
A5: Service Type: PAAS
A6: Part | B6: Description | C6: Part Qty | D6: Instance Qty | E6: Usage Qty | F6: Unit Price | G6: Monthly Cost | H6: Custom Label | I6: Custom Note
B7: cgia-pro-wrkstn
A8: B95518 | B8: Secure Desktop (Desktop Per Month) | C8: 10 | D8: 1 | E8: 1 | F8: 20 | G8: 200
A9: B97384 | B9: Compute - Standard - E5 - OCPU (OCPU Per Hour) Capacity Type: On-Demand | C9: 4 | D9: 10 | E9: 730 | F9: 0.03 | G9: 876
A10: B97385 | B10: Compute - Standard - E5 - Memory (Gigabyte Per Hour) Capacity Type: On-Demand | C10: 32 | D10: 10 | E10: 730 | F10: 0.002 | G10: 467.2
B11: Boot Volume
A12: B91961 | B12: Storage - Block Volume - Storage (Gigabyte Storage Capacity Per Month) | C12: 200 | D12: 10 | E12: 1 | F12: 0.0255 | G12: 51
A13: B91962 | B13: Storage - Block Volume - Performance Units (Performance Units Per Gigabyte Per Month) | C13: 2000 | D13: 10 | E13: 1 | F13: 0.0017 | G13: 34
B14: cgia-prd-web
A15: B111129 | B15: OCI - Compute - Standard - E6 - OCPU (OCPU Per Hour) Capacity Type: On-Demand | C15: 1 | D15: 2 | E15: 730 | F15: 0.03 | G15: 43.8
A16: B111130 | B16: OCI - Compute - Standard - E6 - Memory (Gigabyte Per Hour) Capacity Type: On-Demand | C16: 4 | D16: 2 | E16: 730 | F16: 0.002 | G16: 11.68
B17: Boot Volume
A18: B91961 | B18: Storage - Block Volume - Storage (Gigabyte Storage Capacity Per Month) | C18: 98.11828 | D18: 2 | E18: 1 | F18: 0.0255 | G18: 5.0040323
A19: B91962 | B19: Storage - Block Volume - Performance Units (Performance Units Per Gigabyte Per Month) | C19: 981.1828 | D19: 2 | E19: 1 | F19: 0.0017 | G19: 3.3360215
A20: B88318 | B20: Compute - Windows OS (OCPU Per Hour) | C20: 1 | D20: 2 | E20: 730 | F20: 0.092 | G20: 134.32
B21: cgia-gismon
A22: B111129 | B22: OCI - Compute - Standard - E6 - OCPU (OCPU Per Hour) Capacity Type: On-Demand | C22: 2 | D22: 1 | E22: 730 | F22: 0.03 | G22: 43.8
A23: B111130 | B23: OCI - Compute - Standard - E6 - Memory (Gigabyte Per Hour) Capacity Type: On-Demand | C23: 16 | D23: 1 | E23: 730 | F23: 0.002 | G23: 23.36
B24: Boot Volume
A25: B91961 | B25: Storage - Block Volume - Storage (Gigabyte Storage Capacity Per Month) | C25: 98.11828 | D25: 1 | E25: 1 | F25: 0.0255 | G25: 2.5020161
A26: B91962 | B26: Storage - Block Volume - Performance Units (Performance Units Per Gigabyte Per Month) | C26: 981.1828 | D26: 1 | E26: 1 | F26: 0.0017 | G26: 1.6680108
A27: B88318 | B27: Compute - Windows OS (OCPU Per Hour) | C27: 2 | D27: 1 | E27: 730 | F27: 0.092 | G27: 134.32
B28: cgia-prd-portal
A29: B111129 | B29: OCI - Compute - Standard - E6 - OCPU (OCPU Per Hour) Capacity Type: On-Demand | C29: 2 | D29: 2 | E29: 730 | F29: 0.03 | G29: 87.6
A30: B111130 | B30: OCI - Compute - Standard - E6 - Memory (Gigabyte Per Hour) Capacity Type: On-Demand | C30: 16 | D30: 2 | E30: 730 | F30: 0.002 | G30: 46.72
B31: Boot Volume
A32: B91961 | B32: Storage - Block Volume - Storage (Gigabyte Storage Capacity Per Month) | C32: 98.11828 | D32: 2 | E32: 1 | F32: 0.0255 | G32: 5.0040323
A33: B91962 | B33: Storage - Block Volume - Performance Units (Performance Units Per Gigabyte Per Month) | C33: 981.1828 | D33: 2 | E33: 1 | F33: 0.0017 | G33: 3.3360215
A34: B88318 | B34: Compute - Windows OS (OCPU Per Hour) | C34: 2 | D34: 2 | E34: 730 | F34: 0.092 | G34: 268.64
B35: cgia-prd-srvhst
A36: B111129 | B36: OCI - Compute - Standard - E6 - OCPU (OCPU Per Hour) Capacity Type: On-Demand | C36: 4 | D36: 2 | E36: 730 | F36: 0.03 | G36: 175.2
A37: B111130 | B37: OCI - Compute - Standard - E6 - Memory (Gigabyte Per Hour) Capacity Type: On-Demand | C37: 32 | D37: 2 | E37: 730 | F37: 0.002 | G37: 93.44
B38: Boot Volume
A39: B91961 | B39: Storage - Block Volume - Storage (Gigabyte Storage Capacity Per Month) | C39: 98.11828 | D39: 2 | E39: 1 | F39: 0.0255 | G39: 5.0040323
A40: B91962 | B40: Storage - Block Volume - Performance Units (Performance Units Per Gigabyte Per Month) | C40: 981.1828 | D40: 2 | E40: 1 | F40: 0.0017 | G40: 3.3360215
...

Sheet AWS Estimate
A1: Estimate summary
A2: Upfront cost | B2: Monthly cost | C2: Total 12 months cost | D2: Currency
A3: 0 | B3: 10382.46 | C3: 124589.52 | D3: USD
C4: * Includes upfront cost
A7: Detailed Estimate
A8: Group hierarchy | B8: Region | C8: Description | D8: Service | E8: Upfront | F8: Monthly | G8: First 12 months total | H8: Currency | I8: Status | J8: Configuration summary
A9: CUSTOMER AWS BOM Draft | B9: US East (N. Virginia) | C9: cgia-prd-web | D9: Amazon EC2 | E9: 0 | F9: 319.5632 | G9: 3834.76 | H9: USD | J9: Tenancy (Shared Instances), Operating system (Windows Server), Workload (Consistent, Number of instances: 2), Advance EC2 instance (m7a.large), Pricing strategy (On-Demand Utilization: 730 Hours/Month), Enable monitoring (disabled), EBS Storage amount (100 GB), DT Inbound: Not selected (0 TB per month), DT Outbound: Not selected (0 TB per month), DT Intra-Region: (0 TB per month)
A10: CUSTOMER AWS BOM Draft | B10: US East (N. Virginia) | C10: cgia-gismon | D10: Amazon EC2 | E10: 0 | F10: 311.5632 | G10: 3738.76 | H10: USD | J10: Tenancy (Shared Instances), Operating system (Windows Server), Workload (Consistent, Number of instances: 1), Advance EC2 instance (m7a.xlarge), Pricing strategy (On-Demand Utilization: 730 Hours/Month), Enable monitoring (disabled), EBS Storage amount (100 GB), DT Inbound: Not selected (0 TB per month), DT Outbound: Not selected (0 TB per month), DT Intra-Region: (0 TB per month)
A11: CUSTOMER AWS BOM Draft | B11: US East (N. Virginia) | C11: cgia-prd-portal | D11: Amazon EC2 | E11: 0 | F11: 623.1264 | G11: 7477.52 | H11: USD | J11: Tenancy (Shared Instances), Operating system (Windows Server), Workload (Consistent, Number of instances: 2), Advance EC2 instance (m7a.xlarge), Pricing strategy (On-Demand Utilization: 730 Hours/Month), Enable monitoring (disabled), EBS Storage amount (100 GB), DT Inbound: Not selected (0 TB per month), DT Outbound: Not selected (0 TB per month), DT Intra-Region: (0 TB per month)
A12: CUSTOMER AWS BOM Draft | B12: US East (N. Virginia) | C12: cgia-prd-srvhst | D12: Amazon EC2 | E12: 0 | F12: 1230.2528 | G12: 14763.03 | H12: USD | J12: Tenancy (Shared Instances), Operating system (Windows Server), Workload (Consistent, Number of instances: 2), Advance EC2 instance (m7a.2xlarge), Pricing strategy (On-Demand Utilization: 730 Hours/Month), Enable monitoring (disabled), EBS Storage amount (100 GB), DT Inbound: Not selected (0 TB per month), DT Outbound: Not selected (0 TB per month), DT Intra-Region: (0 TB per month)
A13: CUSTOMER AWS BOM Draft | B13: US East (N. Virginia) | C13: cgia-prd-srvmap | D13: Amazon EC2 | E13: 0 | F13: 1230.2528 | G13: 14763.03 | H13: USD | J13: Tenancy (Shared Instances), Operating system (Windows Server), Workload (Consistent, Number of instances: 2), Advance EC2 instance (m7a.2xlarge), Pricing strategy (On-Demand Utilization: 730 Hours/Month), Enable monitoring (disabled), EBS Storage amount (100 GB), DT Inbound: Not selected (0 TB per month), DT Outbound: Not selected (0 TB per month), DT Intra-Region: (0 TB per month)
A14: CUSTOMER AWS BOM Draft | B14: US East (N. Virginia) | C14: nms-prd-srvnb | D14: Amazon EC2 | E14: 0 | F14: 1230.2528 | G14: 14763.03 | H14: USD | J14: Tenancy (Shared Instances), Operating system (Windows Server), Workload (Consistent, Number of instances: 2), Advance EC2 instance (m7a.2xlarge), Pricing strategy (On-Demand Utilization: 730 Hours/Month), Enable monitoring (disabled), EBS Storage amount (100 GB), DT Inbound: Not selected (0 TB per month), DT Outbound: Not selected (0 TB per month), DT Intra-Region: (0 TB per month)
A15: CUSTOMER AWS BOM Draft | B15: US East (N. Virginia) | C15: nms-prd-srvimg | D15: Amazon EC2 | E15: 0 | F15: 1230.2528 | G15: 14763.03 | H15: USD | J15: Tenancy (Shared Instances), Operating system (Windows Server), Workload (Consistent, Number of instances: 2), Advance EC2 instance (m7a.2xlarge), Pricing strategy (On-Demand Utilization: 730 Hours/Month), Enable monitoring (disabled), EBS Storage amount (100 GB), DT Inbound: Not selected (0 TB per month), DT Outbound: Not selected (0 TB per month), DT Intra-Region: (0 TB per month)
A16: CUSTOMER AWS BOM Draft | B16: US East (N. Virginia) | C16: nms-prd-srvhst | D16: Amazon EC2 | E16: 0 | F16: 1230.2528 | G16: 14763.03 | H16: USD | J16: Tenancy (Shared Instances), Operating system (Windows Server), Workload (Consistent, Number of instances: 2), Advance EC2 instance (m7a.2xlarge), Pricing strategy (On-Demand Utilization: 730 Hours/Month), Enable monitoring (disabled), EBS Storage amount (100 GB), DT Inbound: Not selected (0 TB per month), DT Outbound: Not selected (0 TB per month), DT Intra-Region: (0 TB per month)
A17: CUSTOMER AWS BOM Draft | B17: US East (N. Virginia) | C17: cgia-prd-dsrel | D17: Amazon EC2 | E17: 0 | F17: 623.1264 | G17: 7477.52 | H17: USD | J17: Tenancy (Shared Instances), Operating system (Windows Server), Workload (Consistent, Number of instances: 2), Advance EC2 instance (m7a.xlarge), Pricing strategy (On-Demand Utilization: 730 Hours/Month), Enable monitoring (disabled), EBS Storage amount (100 GB), DT Inbound: Not selected (0 TB per month), DT Outbound: Not selected (0 TB per month), DT Intra-Region: (0 TB per month)
A18: CUSTOMER AWS BOM Draft | B18: US East (N. Virginia) | C18: cgia-prd-egdb | D18: Amazon EC2 | E18: 0 | F18: 734.956 | G18: 8819.47 | H18: USD | J18: Tenancy (Shared Instances), Operating system (Windows Server), Workload (Consistent, Number of instances: 1), Advance EC2 instance (r7i.2xlarge), Pricing strategy (On-Demand Utilization: 730 Hours/Month), Enable monitoring (disabled), EBS Storage amount (1000 GB), DT Inbound: Not selected (0 TB per month), DT Outbound: Not selected (0 TB per month), DT Intra-Region: (0 TB per month)
A19: CUSTOMER AWS BOM Draft | B19: US East (N. Virginia) | C19: S3 Storage | D19: S3 Standard | E19: 0 | F19: 23.05 | G19: 276.6 | H19: USD | J19: S3 Standard storage (1000 GB per month), PUT, COPY, POST, LIST requests to S3 Standard (10000), GET, SELECT, and all other requests from S3 Standard (10000)
A20: CUSTOMER AWS BOM Draft | B20: US East (N. Virginia) | C20: S3 Storage | D20: Data Transfer | E20: 0 | F20: 0 | G20: 0 | H20: USD | J20: DT Inbound: Not selected (0 TB per month), DT Outbound: Not selected (0 TB per month)
... A25: CUSTOMER AWS BOM Draft | B25: US East (N. Virginia) | C25: Data Transfer | D25: AWS Data Transfer | E25: 0 | F25: 0 | G25: 0 | H25: USD | J25: DT Inbound: Internet (1 TB per month), DT Outbound: Internet (2 TB per month), DT Intra-Region: (0 TB per month), Data transfer cost (184.32)
A26: CUSTOMER AWS BOM Draft | B26: US East (N. Virginia) | C26: Direct Connect | D26: AWS Direct Connect | E26: 0 | F26: 478.96 | G26: =PRODUCT(F26*12) -> 5747.52 | H26: USD | J26: Number of ports (2), Location (Digital Realty IAD38, Ashburn, VA), Port type (Dedicated), Port capacity (1G)
A27: Monthly | F27: =SUM(F9:F26) -> 10861.429
A28: Annual | F28: =PRODUCT(F27*12) -> 130337.15
A29: Acknowledgement
A30: * AWS Pricing Calculator provides only an estimate of your AWS fees and doesn't include any taxes that might apply. Your actual fees depend on a variety of factors, including your actual usage of AWS services.
